Workbook
Name squat1A: Results!$N$12:$W$16
Name deadlift3B: Results!$Y$108:$AH$112
Name Session5Distribution: Definitions!$A$40
Name benchpress1B: Results!$Y$53:$AH$57
Name squat4B: Results!$Y$33:$AH$37
Name benchpress4C: Results!$AJ$74:$AS$78
Name Session3Distribution: Definitions!$A$28:$A$33
Name benchpress4A: Results!$N$74:$W$78
Name deadlift1C: Results!$AJ$94:$AS$98
Name deadlift1B: Results!$Y$94:$AH$98
Name squat1C: Results!$AJ$12:$AS$16
Name benchpress3B: Results!$Y$67:$AH$71
Name Week2Distribution: Definitions!$G$21:$H$22
Name benchpress2B: Results!$Y$60:$AH$64
Name squat2B: Results!$Y$19:$AH$23
Name squat3A: Results!$N$26:$W$30
Name squat3B: Results!$Y$26:$AH$30
Name deadlift4B: Results!$Y$115:$AH$119
Name deadlift1A: Results!$N$94:$W$98
Name squat3C: Results!$AJ$26:$AS$30
Name deadlift4C: Results!$AJ$115:$AS$119
Name deadlift2A: Results!$N$101:$W$105
Name benchpress1C: Results!$AJ$53:$AS$57
Name deadlift2B: Results!$Y$101:$AH$105
Name benchpress3C: Results!$AJ$67:$AS$71
Name squat2C: Results!$AJ$19:$AS$23
Name squat2A: Results!$N$19:$W$23
Name Session2Distribution: Definitions!$A$21:$A$25
Name benchpress3A: Results!$N$67:$W$71
Name deadlift3C: Results!$AJ$108:$AS$112
Name squat4C: Results!$AJ$33:$AS$37
Name benchpress2C: Results!$AJ$60:$AS$64
Name Session4Distribution: Definitions!$A$36:$A$37
Name squat1B: Results!$Y$12:$AH$16
Name deadlift4A: Results!$N$115:$W$119
Name benchpress1A: Results!$N$53:$W$57
Name deadlift2C: Results!$AJ$101:$AS$105
Name benchpress4B: Results!$Y$74:$AH$78
Name Week3Distribution: Definitions!$G$28:$G$33
Name deadlift3A: Results!$N$108:$W$112
Name squat4A: Results!$N$33:$W$37
Name benchpress2A: Results!$N$60:$W$64

Sheet Input
A2: Name | B2: Kateřina Balášová
A3: Lift | B3: squat | C3: advanced
B4: prep
A5: 1RM | B5: 140
A6: Rounding | B6: 2.5
A7: Monthly NL | B7: 220
A8: Cycle [weeks] | B8: 4
A9: Cycle NL | B9: =ROUNDUP(B7*B8/4,0) -> 220
A11: Zone | B11: Weight [kg] | C11: Weight [%] | D11: Percentage | E11: Reps | H11: Weight Hint | I11: Range | J11: Wiggle
A12: 50-60% | B12: 80 | C12: =B12/$B$5 -> 0.57142857 | D12: 0 | E12: =ROUND($B$7*D12,0) -> 0 | H12: =MROUND($B$5*55%,$B$6) -> 77.5 | I12: ="± " & MROUND(H12*J12,$B$6) & "kg" -> ± 2,5kg | J12: 0.025
A13: 61-70% | B13: 90 | C13: =B13/$B$5 -> 0.64285714 | D13: =100%-D14-D15-D16-D17-D12 -> 0.38636364 | E13: =ROUND($B$7*D13,0) -> 85 | H13: =MROUND($B$5*65%,$B$6) -> 90 | I13: ="± " & MROUND(H13*J13,$B$6) & "kg" -> ± 2,5kg | J13: 0.025
A14: 71-80% | B14: 105 | C14: =B14/$B$5 -> 0.75 | D14: 0.42 | E14: =ROUND($B$7*D14,0) -> 92 | H14: =MROUND($B$5*75%,$B$6) -> 105 | I14: ="± " & MROUND(H14*J14,$B$6) & "kg" -> ± 2,5kg | J14: 0.02
A15: 81-90% | B15: 120 | C15: =B15/$B$5 -> 0.85714286 | D15: 0.18 | E15: =ROUND($B$7*D15,0) -> 40 | H15: =MROUND($B$5*85%,$B$6) -> 120 | I15: ="± " & MROUND(H15*J15,$B$6) & "kg" -> ± 2,5kg | J15: 0.02
A16: 91-94% | B16: 130 | C16: =B16/$B$5 -> 0.92857143 | D16: =E16/B9 -> 0.013636364 | E16: 3 | H16: =MROUND($B$5*92.5%,$B$6) -> 130 | I16: ="± " & MROUND(H16*J16,$B$6) & "kg" -> ± 5kg | J16: 0.03
A17: 95-100% | B17: 135 | C17: =B17/$B$5 -> 0.96428571 | D17: =E17/B9 -> 0 | E17: 0 | H17: =MROUND($B$5*95%,$B$6) -> 132.5 | I17: ="± " & MROUND(H17*J17,$B$6) & "kg" -> ± 5kg | J17: 0.03
A19: (H)ARI | B19: =B12/B5*D12+B13/B5*D13+B14/B5*D14+B15/B5*D15+B16/B5*D16+B17/B5*D17 -> 0.73032468
A21: Main variant | B21: 3a | C21: =VLOOKUP($B$21,IF(C3="advanced", Definitions!$J$3:$N$18, IF(C3="elite", Definitions!$O$3:$S$18, Definitions!$A$3:$E$18)),2,FALSE) -> 17 | D21: =VLOOKUP($B$21,IF(C3="advanced", Definitions!$J$3:$N$18, IF(C3="elite", Definitions!$O$3:$S$18, Definitions!$A$3:$E$18)),3,FALSE) -> 22 | E21: =VLOOKUP(B21,IF(C3="advanced", Definitions!$J$3:$N$18, IF(C3="elite", Definitions!$O$3:$S$18, Definitions!$A$3:$E$18)),4,FALSE) -> 33 | F21: =VLOOKUP(B21,IF(C3="advanced", Definitions!$J$3:$N$18, IF(C3="elite", Definitions!$O$3:$S$18, Definitions!$A$3:$E$18)),5,FALSE) -> 28
A22: 81-90 variant | B22: 2a | C22: =VLOOKUP($B$22,IF(C3="advanced", Definitions!$J$3:$N$18, IF(C3="elite", Definitions!$O$3:$S$18, Definitions!$A$3:$E$18)),2,FALSE) -> 17 | D22: =VLOOKUP($B$22,IF(C3="advanced", Definitions!$J$3:$N$18, IF(C3="elite", Definitions!$O$3:$S$18, Definitions!$A$3:$E$18)),3,FALSE) -> 33 | E22: =VLOOKUP($B$22,IF(C3="advanced", Definitions!$J$3:$N$18, IF(C3="elite", Definitions!$O$3:$S$18, Definitions!$A$3:$E$18)),4,FALSE) -> 28 | F22: =VLOOKUP($B$22,IF(C3="advanced", Definitions!$J$3:$N$18, IF(C3="elite", Definitions!$O$3:$S$18, Definitions!$A$3:$E$18)),5,FALSE) -> 22
A24: Int.zone / Week | B24: 1 | C24: 2 | D24: 3 | E24: 4 | F24: 5 | G24: 6
A25: %1RM / NL | B25: =ROUND($B$9*C21/100,0) -> 37 | C25: =ROUND($B$9*D21/100,0) -> 48 | D25: =ROUND($B$9*E21/100,0) -> 73 | E25: =ROUND($B$9*F21/100,0) -> 62 | H25: =sum(B25:G25) -> 220
A26: 0.55 | B26: =ROUND($D12*$B$9*C$21/100,0) -> 0 | C26: =ROUND($D12*$B$9*D$21/100,0) -> 0 | D26: =ROUND($D12*$B$9*E$21/100,0) -> 0 | E26: =ROUND($D12*$B$9*F$21/100,0) -> 0
A27: 0.65 | B27: =ROUND($D13*$B$9*C$21/100,0) -> 14 | C27: =ROUND($D13*$B$9*D$21/100,0) -> 19 | D27: =ROUND($D13*$B$9*E$21/100,0) -> 28 | E27: =ROUND($D13*$B$9*F$21/100,0) -> 24
A28: 0.75 | B28: =B25-B26-B27-B29-B30-B31 -> 16 | C28: =C25-C26-C27-C29-C30-C31 -> 15 | D28: =D25-D26-D27-D29-D30-D31 -> 33 | E28: =E25-E26-E27-E29-E30-E31 -> 28
A29: 0.85 | B29: =ROUND($D15*$B$9*C$22/100,0) -> 7 | C29: =ROUND($D15*$B$9*D$22/100,0) -> 13 | D29: =ROUND($D15*$B$9*E$22/100,0) -> 11 | E29: =ROUND($D15*$B$9*F$22/100,0) -> 9
A30: 0.925 | B30: 0 | C30: 1 | D30: 1 | E30: 1
A31: 0.95 | B31: 0 | C31: 0 | D31: 0 | E31: 0
A32: ARI | B32: =ROUND(B26/B25*$B12/$B$5+B27/B25*$B13/$B$5+B28/B25*$B14/$B$5+B29/B25*$B15/$B$5+B30/B25*$B16/$B$5+B31/B25*$B17/$B$5,3)*100 -> 73 | C32: =ROUND(C26/C25*$B12/$B$5+C27/C25*$B13/$B$5+C28/C25*$B14/$B$5+C29/C25*$B15/$B$5+C30/C25*$B16/$B$5+C31/C25*$B17/$B$5,3)*100 -> 74 | D32: =ROUND(D26/D25*$B12/$B$5+D27/D25*$B13/$B$5+D28/D25*$B14/$B$5+D29/D25*$B15/$B$5+D30/D25*$B16/$B$5+D31/D25*$B17/$B$5,3)*100 -> 72.7 | E32: =ROUND(E26/E25*$B12/$B$5+E27/E25*$B13/$B$5+E28/E25*$B14/$B$5+E29/E25*$B15/$B$5+E30/E25*$B16/$B$5+E31/E25*$B17/$B$5,3)*100 -> 72.7
A34: 3 | B34: days / week | H34: {=INDIRECT("Definitions!" & "Session" & A34 & "Distribution")} -> d25_33_42 | I34: {=INDIRECT("Definitions!" & "Week" & A34 & "Distribution")} -> LMH
A35: d25_33_42 | B35: distribution in a week | H35: d20_35_45 | I35: LHM
A36: LHM | B36: #reps | C36: #reps | D36: #reps | E36: #reps | H36: d22_28_50 | I36: MLH
A37: {=VLOOKUP($A$35, Definitions!$A$21:$F$40, MATCH(MID($A$36, 1, 1), {"L"; "M"; "H"}, 0) + 1, FALSE)} -> 25 | B37: =ROUND(B$25*$A37/100,0) -> 9 | C37: =ROUND(C$25*$A37/100,0) -> 12 | D37: =ROUND(D$25*$A37/100,0) -> 18 | E37: =ROUND(E$25*$A37/100,0) -> 16 | H37: d20_30_50 | I37: MHL
A38: {=IF(LEN($A$36)>=2, VLOOKUP($A$35, Definitions!$A$21:$F$40, MATCH(MID($A$36, 2, 1), {"L"; "M"; "H"}, 0) + 1, FALSE), "")} -> 42 | B38: =ROUND(B$25*$A38/100,0) -> 16 | C38: =ROUND(C$25*$A38/100,0) -> 20 | D38: =ROUND(D$25*$A38/100,0) -> 31 | E38: =ROUND(E$25*$A38/100,0) -> 26 | H38: d15_35_50 | I38: HLM
A39: {=IF(LEN($A$36)>=3, IF(ISERROR(MATCH(MID($A$36, 3, 1), {"L"; "M"; "H"}, 0)), 0, VLOOKUP($A$35, Definitions!$A$21:$F$40, MATCH(MID($A$36, 3, 1), {"L"; "M"; "H"}, 0) + 1, FALSE)), 0)} -> 33 | B39: =ROUND(B$25*$A39/100,0) -> 12 | C39: =ROUND(C$25*$A39/100,0) -> 16 | D39: =ROUND(D$25*$A39/100,0) -> 24 | E39: =ROUND(E$25*$A39/100,0) -> 20 | H39: d15_30_55 | I39: HML
A41: 2 | B41: days / week | H41: {=INDIRECT("Definitions!" & "Session" & A41 & "Distribution")} -> d40_60 | I41: {=INDIRECT("Definitions!" & "Week" & A41 & "Distribution")} -> MH
A42: d40_60 | B42: distribution in a week | H42: d35_65 | I42: HM
A43: MH | B43: #reps | C43: #reps | D43: #reps | E43: #reps | H43: d30_70
A44: {=VLOOKUP($A$42, Definitions!$A$21:$F$40, MATCH(MID($A$43, 1, 1), {"L"; "M"; "H"}, 0) + 1, FALSE)} -> 40 | B44: =ROUND(B$25*$A44/100,0) -> 15 | C44: =ROUND(C$25*$A44/100,0) -> 19 | D44: =ROUND(D$25*$A44/100,0) -> 29 | E44: =ROUND(E$25*$A44/100,0) -> 25 | H44: d25_75
A45: {=IF(LEN($A$43)>=2, VLOOKUP($A$42, Definitions!$A$21:$F$40, MATCH(MID($A$43, 2, 1), {"L"; "M"; "H"}, 0) + 1, FALSE), "")} -> 60 | B45: =ROUND(B$25*$A45/100,0) -> 22 | C45: =ROUND(C$25*$A45/100,0) -> 29 | D45: =ROUND(D$25*$A45/100,0) -> 44 | E45: =ROUND(E$25*$A45/100,0) -> 37 | H45: d20_80
A46: {=IF(LEN($A$43)>=3, IF(ISERROR(MATCH(MID($A$43, 3, 1), {"L"; "M"; "H"}, 0)), 0, VLOOKUP($A$42, Definitions!$A$21:$F$40, MATCH(MID($A$43, 3, 1), {"L"; "M"; "H"}, 0) + 1, FALSE)), 0)} -> 0 | B46: =ROUND(B$25*$A46/100,0) -> 0 | C46: =ROUND(C$25*$A46/100,0) -> 0 | D46: =ROUND(D$25*$A46/100,0) -> 0 | E46: =ROUND(E$25*$A46/100,0) -> 0
A48: Name | B48: Kateřina Balášová
...

Sheet Results
A1: Name | G1: lift | N1: 1RM | P1: round | R1: cycle | T1: NL | V1: NL>90 | Y1: ARI | AA1: Main | AC1: 8190
A2: =Input!B2 -> Kateřina Balášová | G2: =Input!B3 -> squat | N2: =Input!B5 -> 140 | P2: =Input!B6 -> 2.5 | R2: =Input!B4 -> prep | T2: =Input!B9 -> 220 | V2: =Input!E16+Input!E17 -> 3 | Y2: =Input!B19 -> 0.73032468 | AA2: =Input!B21 -> 3a | AC2: =Input!B22 -> 2a
A4: Notes | E4: Comp variant
E5: Comp paused
E6: High Bar
A9: week # | D9: Main Weight | H9: Assist Weight | J9: Assist Weight | L9: Assist Weight | M9: Range ± | N9: session A | Y9: session B | AJ9: session C
N10: sets | Y10: sets | AJ10: sets
B11: lift | C11: %1RM | E11: #reps | F11: rep rng | G11: % of main | I11: % of main | K11: % of main | N11: #1 | O11: #2 | P11: #3 | Q11: #4 | R11: #5 | S11: #6 | T11: #7 | U11: #8 | V11: #9 | W11: #10 | Y11: #1 | Z11: #2 | AA11: #3 | AB11: #4 | AC11: #5 | AD11: #6 | AE11: #7 | AF11: #8 | AG11: #9 | AH11: #10 | AJ11: #1 | AK11: #2 | AL11: #3 | AM11: #4 | AN11: #5 | AO11: #6 | AP11: #7 | AQ11: #8 | AR11: #9 | AS11: #10
A12: 1 | B12: =Input!$B$3 -> squat | C12: =Input!C13 -> 0.64285714 | D12: =Input!B13 -> 90 | E12: =Input!B27 -> 14 | F12: 45477 | G12: 0.9 | H12: =MROUND($D12*G12,Input!$B$6) -> 80 | I12: 0.9 | J12: =MROUND($D12*I12,Input!$B$6) -> 80 | M12: =Input!I13 -> ± 2,5kg | N12: 5 | X12: =SUM(N12:W16) -> 9 | Y12: 5 | AI12: =SUM(Y12:AH16) -> 17 | AJ12: 4 | AT12: =SUM(AJ12:AS16) -> 11 | AU12: =E12-SUM(N12:W12)-SUM(Y12:AH12)-SUM(AJ12:AS12) -> 0
C13: =Input!C14 -> 0.75 | D13: =Input!B14 -> 105 | E13: =Input!B28 -> 16 | F13: 45446 | G13: 0.9 | H13: =MROUND($D13*G13,Input!$B$6) -> 95 | I13: 0.9 | J13: =MROUND($D13*I13,Input!$B$6) -> 95 | M13: =Input!I14 -> ± 2,5kg | O13: 4 | Z13: 4 | AC13: 4 | AK13: 4 | AU13: =E13-SUM(N13:W13)-SUM(Y13:AH13)-SUM(AJ13:AS13) -> 0
C14: =Input!C15 -> 0.85714286 | D14: =Input!B15 -> 120 | E14: =Input!B29 -> 7 | F14: 45384 | G14: 0.9 | H14: =MROUND($D14*G14,Input!$B$6) -> 107.5 | I14: 0.9 | J14: =MROUND($D14*I14,Input!$B$6) -> 107.5 | M14: =Input!I15 -> ± 2,5kg | AA14: 2 | AB14: 2 | AL14: 3 | AU14: =E14-SUM(N14:W14)-SUM(Y14:AH14)-SUM(AJ14:AS14) -> 0
C15: =Input!C16 -> 0.92857143 | D15: =Input!B16 -> 130 | E15: =Input!B30 -> 0 | F15: 1 | M15: =Input!I16 -> ± 5kg | AU15: =E15-SUM(N15:W15)-SUM(Y15:AH15)-SUM(AJ15:AS15) -> 0
C16: =Input!C17 -> 0.96428571 | D16: =Input!B17 -> 135 | E16: =Input!B31 -> 0 | F16: 1 | M16: =Input!I17 -> ± 5kg | AU16: =E16-SUM(N16:W16)-SUM(Y16:AH16)-SUM(AJ16:AS16) -> 0
C17: RPE | X17: =Input!B37 -> 9 | AI17: =Input!B38 -> 16 | AT17: =Input!B39 -> 12
X18: =Input!B44 -> 15 | AI18: =Input!B45 -> 22 | AT18: =Input!B46 -> 0
A19: 2 | B19: =Input!$B$3 -> squat | C19: =Input!C13 -> 0.64285714 | D19: =Input!B13 -> 90 | E19: =Input!C27 -> 19 | F19: 45477 | G19: 0.9 | H19: =MROUND($D19*G19,Input!$B$6) -> 80 | I19: 0.9 | J19: =MROUND($D19*I19,Input!$B$6) -> 80 | M19: =M12 -> ± 2,5kg | N19: 5 | O19: 5 | X19: =SUM(N19:W23) -> 12 | Y19: 5 | AI19: =SUM(Y19:AH23) -> 20 | AJ19: 4 | AT19: =SUM(AJ19:AS23) -> 16 | AU19: =E19-SUM(N19:W19)-SUM(Y19:AH19)-SUM(AJ19:AS19) -> 0
C20: =Input!C14 -> 0.75 | D20: =Input!B14 -> 105 | E20: =Input!C28 -> 15 | F20: 45446 | G20: 0.9 | H20: =MROUND($D20*G20,Input!$B$6) -> 95 | I20: 0.9 | J20: =MROUND($D20*I20,Input!$B$6) -> 95 | M20: =M13 -> ± 2,5kg | P20: 2 | Z20: 4 | AC20: 3 | AK20: 3 | AN20: 3 | AU20: =E20-SUM(N20:W20)-SUM(Y20:AH20)-SUM(AJ20:AS20) -> 0
C21: =Input!C15 -> 0.85714286 | D21: =Input!B15 -> 120 | E21: =Input!C29 -> 13 | F21: 45384 | G21: 0.9 | H21: =MROUND($D21*G21,Input!$B$6) -> 107.5 | I21: 0.9 | J21: =MROUND($D21*I21,Input!$B$6) -> 107.5 | M21: =M14 -> ± 2,5kg | AA21: 4 | AB21: 4 | AL21: 2 | AO21: 3 | AU21: =E21-SUM(N21:W21)-SUM(Y21:AH21)-SUM(AJ21:AS21) -> 0
C22: =Input!C16 -> 0.92857143 | D22: =Input!B16 -> 130 | E22: =Input!C30 -> 1 | F22: 1 | M22: =M15 -> ± 5kg | AM22: 1 | AU22: =E22-SUM(N22:W22)-SUM(Y22:AH22)-SUM(AJ22:AS22) -> 0
C23: =Input!C17 -> 0.96428571 | D23: =Input!B17 -> 135 | E23: =Input!C31 -> 0 | F23: 1 | M23: =M16 -> ± 5kg | AU23: =E23-SUM(N23:W23)-SUM(Y23:AH23)-SUM(AJ23:AS23) -> 0
C24: RPE | X24: =Input!C37 -> 12 | AI24: =Input!C38 -> 20 | AT24: =Input!C39 -> 16
X25: =Input!C44 -> 19 | AI25: =Input!C45 -> 29 | AT25: =Input!C46 -> 0
A26: 3 | B26: =Input!$B$3 -> squat | C26: =Input!C13 -> 0.64285714 | D26: =Input!B13 -> 90 | E26: =Input!D27 -> 28 | F26: 45477 | G26: 0.9 | H26: =MROUND($D26*G26,Input!$B$6) -> 80 | I26: 0.9 | J26: =MROUND($D26*I26,Input!$B$6) -> 80 | M26: =M12 -> ± 2,5kg | N26: 5 | X26: =SUM(N26:W30) -> 18 | Y26: 6 | AB26: 5 | AE26: 6 | AI26: =SUM(Y26:AH30) -> 31 | AJ26: 6 | AT26: =SUM(AJ26:AS30) -> 24 | AU26: =E26-SUM(N26:W26)-SUM(Y26:AH26)-SUM(AJ26:AS26) -> 0
C27: =Input!C14 -> 0.75 | D27: =Input!B14 -> 105 | E27: =Input!D28 -> 33 | F27: 45446 | G27: 0.9 | H27: =MROUND($D27*G27,Input!$B$6) -> 95 | I27: 0.9 | J27: =MROUND($D27*I27,Input!$B$6) -> 95 | M27: =M13 -> ± 2,5kg | O27: 5 | Q27: 5 | Z27: 4 | AC27: 4 | AK27: 4 | AN27: 4 | AO27: 3 | AP27: 4 | AU27: =E27-SUM(N27:W27)-SUM(Y27:AH27)-SUM(AJ27:AS27) -> 0
C28: =Input!C15 -> 0.85714286 | D28: =Input!B15 -> 120 | E28: =Input!D29 -> 11 | F28: 45384 | G28: 0.9 | H28: =MROUND($D28*G28,Input!$B$6) -> 107.5 | I28: 0.9 | J28: =MROUND($D28*I28,Input!$B$6) -> 107.5 | M28: =M14 -> ± 2,5kg | P28: 3 | AA28: 3 | AD28: 3 | AL28: 2 | AU28: =E28-SUM(N28:W28)-SUM(Y28:AH28)-SUM(AJ28:AS28) -> 0
C29: =Input!C16 -> 0.92857143 | D29: =Input!B16 -> 130 | E29: =Input!D30 -> 1 | F29: 1 | M29: =M15 -> ± 5kg | AM29: 1 | AU29: =E29-SUM(N29:W29)-SUM(Y29:AH29)-SUM(AJ29:AS29) -> 0
C30: =Input!C17 -> 0.96428571 | D30: =Input!B17 -> 135 | E30: =Input!D31 -> 0 | F30: 1 | M30: =M16 -> ± 5kg | AU30: =E30-SUM(N30:W30)-SUM(Y30:AH30)-SUM(AJ30:AS30) -> 0
C31: RPE | X31: =Input!D37 -> 18 | AI31: =Input!D38 -> 31 | AT31: =Input!D39 -> 24
X32: =Input!D44 -> 29 | AI32: =Input!D45 -> 44 | AT32: =Input!D46 -> 0
A33: 4 | B33: =Input!$B$3 -> squat | C33: =Input!C13 -> 0.64285714 | D33: =Input!B13 -> 90 | E33: =Input!E27 -> 24 | F33: 45477 | G33: 0.9 | H33: =MROUND($D33*G33,Input!$B$6) -> 80 | I33: 0.9 | J33: =MROUND($D33*I33,Input!$B$6) -> 80 | M33: =M12 -> ± 2,5kg | N33: 6 | X33: =SUM(N33:W37) -> 15 | Y33: 7 | AB33: 6 | AI33: =SUM(Y33:AH37) -> 27 | AJ33: 5 | AT33: =SUM(AJ33:AS37) -> 20 | AU33: =E33-SUM(N33:W33)-SUM(Y33:AH33)-SUM(AJ33:AS33) -> 0
C34: =Input!C14 -> 0.75 | D34: =Input!B14 -> 105 | E34: =Input!E28 -> 28 | F34: 45446 | G34: 0.9 | H34: =MROUND($D34*G34,Input!$B$6) -> 95 | I34: 0.9 | J34: =MROUND($D34*I34,Input!$B$6) -> 95 | M34: =M13 -> ± 2,5kg | O34: 5 | Z34: 7 | AA34: 7 | AK34: 4 | AN34: 5 | AU34: =E34-SUM(N34:W34)-SUM(Y34:AH34)-SUM(AJ34:AS34) -> 0
C35: =Input!C15 -> 0.85714286 | D35: =Input!B15 -> 120 | E35: =Input!E29 -> 9 | F35: 45384 | G35: 0.9 | H35: =MROUND($D35*G35,Input!$B$6) -> 107.5 | I35: 0.9 | J35: =MROUND($D35*I35,Input!$B$6) -> 107.5 | M35: =M14 -> ± 2,5kg | P35: 4 | AL35: 2 | AO35: 3 | AU35: =E35-SUM(N35:W35)-SUM(Y35:AH35)-SUM(AJ35:AS35) -> 0
C36: =Input!C16 -> 0.92857143 | D36: =Input!B16 -> 130 | E36: =Input!E30 -> 1 | F36: 1 | M36: =M15 -> ± 5kg | AM36: 1 | AU36: =E36-SUM(N36:W36)-SUM(Y36:AH36)-SUM(AJ36:AS36) -> 0
C37: =Input!C17 -> 0.96428571 | D37: =Input!B17 -> 135 | E37: =Input!E31 -> 0 | F37: 1 | M37: =M16 -> ± 5kg | AU37: =E37-SUM(N37:W37)-SUM(Y37:AH37)-SUM(AJ37:AS37) -> 0
C38: RPE | X38: =Input!E37 -> 16 | AI38: =Input!E38 -> 26 | AT38: =Input!E39 -> 20
X39: =Input!E44 -> 25 | AI39: =Input!E45 -> 37 | AT39: =Input!E46 -> 0
A42: Name | G42: lift | N42: 1RM | P42: round | R42: cycle | T42: NL | V42: NL>90 | Y42: ARI | AA42: Main | AC42: 8190
A43: =Input!B2 -> Kateřina Balášová | G43: =Input!B49 -> bench press | N43: =Input!B51 -> 77.5 | P43: =Input!B52 -> 2.5 | R43: =Input!B50 -> prep | T43: =Input!B53 -> 250 | V43: =Input!E62+Input!E63 -> 5 | Y43: =Input!B65 -> 0.77012903 | AA43: =Input!B67 -> 2a | AC43: =Input!B68 -> 1-3a
A45: Notes | E45: Comp variant
E46: Comp variant max grip width
...

Sheet Output
A1: Name | H1: lift | M1: 1RM | O1: round | Q1: cycle | S1: NL | U1: NL>90 | W1: ARI | Y1: Main | AA1: 8190
A2: =Input!B2 -> Kateřina Balášová | H2: =Input!B3 -> squat | M2: =Input!B5 -> 140 | O2: =Input!B6 -> 2.5 | Q2: =Input!B4 -> prep | S2: =Input!B9 -> 220 | U2: =Input!E16+Input!E17 -> 3 | W2: =Input!B19 -> 0.73032468 | Y2: =Input!B21 -> 3a | AA2: =Input!B22 -> 2a
H3: =Input!B49 -> bench press | M3: =Input!B51 -> 77.5 | O3: =Input!B52 -> 2.5 | Q3: =Input!B50 -> prep | S3: =Input!B53 -> 250 | U3: =Input!E62+Input!E63 -> 5 | W3: =Input!B65 -> 0.77012903 | Y3: =Input!B67 -> 2a | AA3: =Input!B68 -> 1-3a
H4: =Input!B95 -> deadlift | M4: =Input!B98 -> 165 | O4: =Input!B99 -> 2.5 | Q4: =Input!B97 -> prep | S4: =Input!B102 -> 180 | U4: =Input!E109+Input!E110 -> 2 | W4: =Input!B112 -> 0.75043771 | Y4: =Input!B114 -> 4-2a | AA4: =Input!B115 -> 3c
W11: week 1 | AH11: week 2 | AS11: week 3 | BD11: week 4
A12: session | C12: lift | O12: weight | W12: sets | AH12: sets | AS12: sets | BD12: sets
W13: #1 | X13: #2 | Y13: #3 | Z13: #4 | AA13: #5 | AB13: #6 | AC13: #7 | AD13: #8 | AE13: #9 | AF13: #10 | AH13: #1 | AI13: #2 | AJ13: #3 | AK13: #4 | AL13: #5 | AM13: #6 | AN13: #7 | AO13: #8 | AP13: #9 | AQ13: #10 | AS13: #1 | AT13: #2 | AU13: #3 | AV13: #4 | AW13: #5 | AX13: #6 | AY13: #7 | AZ13: #8 | BA13: #9 | BB13: #10 | BD13: #1 | BE13: #2 | BF13: #3 | BG13: #4 | BH13: #5 | BI13: #6 | BJ13: #7 | BK13: #8 | BL13: #9 | BM13: #10
A14: A | C14: squat | F14: Comp variant | O14: 90 | Q14: 80 | S14: 80 | W14: 5 | AH14: 5 | AI14: 5
F15: Comp paused | O15: 105 | Q15: 95 | S15: 95 | X15: 4 | AJ15: 2
F16: High Bar | O16: 120 | Q16: 107.5 | S16: 107.5
O17: 130
O18: 135
O19: RPE
C20: benchpress | F20: Comp variant | O20: 50 | Q20: 47.5 | S20: 42.5 | U20: 55 | AH20: 5
F21: Comp variant max grip width | O21: 60 | Q21: 57.5 | S21: 50 | U21: 65 | W21: 5 | AI21: 5 | AL21: 5
F22: Larsen Mid-Grip | O22: 67.5 | Q22: 65 | S22: 57.5 | U22: 75 | X22: 3 | Y22: 3 | AJ22: 2 | AK22: 3
F23: Board | O23: 72.5 | Q23: 70 | S23: 62.5 | U23: 80
O24: 75 | U24: 82.5
O25: RPE
C26: deadlift | F26: Comp Variant | O26: 110 | Q26: 105 | S26: 115 | U26: 120
F27: Sumo | O27: 125 | Q27: 120 | S27: 132.5 | U27: 137.5 | W27: 2 | X27: 2 | Y27: 2 | Z27: 2 | AA27: 2 | AH27: 2 | AI27: 2 | AJ27: 2 | AK27: 2 | AL27: 2 | AM27: 2
F28: Block / Rack | O28: 140 | Q28: 132.5 | S28: 147.5 | U28: 155
O29: 152.5 | Q29: 145 | S29: 160 | U29: 167.5
O30: 157.5 | U30: 172.5
O31: RPE
C32: Assistance / Accessories
C33: Power Clean (+ jerk on last rep) | W33: 5x3 @ up to RPE9 | AH33: 5x3 @ up to RPE9
A39: session | C39: lift | O39: weight | W39: sets | AH39: sets | AS39: sets | BD39: sets
W40: #1 | X40: #2 | Y40: #3 | Z40: #4 | AA40: #5 | AB40: #6 | AC40: #7 | AD40: #8 | AE40: #9 | AF40: #10 | AH40: #1 | AI40: #2 | AJ40: #3 | AK40: #4 | AL40: #5 | AM40: #6 | AN40: #7 | AO40: #8 | AP40: #9 | AQ40: #10 | AS40: #1 | AT40: #2 | AU40: #3 | AV40: #4 | AW40: #5 | AX40: #6 | AY40: #7 | AZ40: #8 | BA40: #9 | BB40: #10 | BD40: #1 | BE40: #2 | BF40: #3 | BG40: #4 | BH40: #5 | BI40: #6 | BJ40: #7 | BK40: #8 | BL40: #9 | BM40: #10
A41: B | C41: benchpress | F41: Comp variant | O41: 50 | Q41: 47.5 | S41: 42.5 | U41: 55 | AH41: 5
F42: Comp variant max grip width | O42: 60 | Q42: 57.5 | S42: 50 | U42: 65 | W42: 4 | Z42: 4 | AI42: 4 | AL42: 4 | AN42: 4
F43: Larsen Mid-Grip | O43: 67.5 | Q43: 65 | S43: 57.5 | U43: 75 | X43: 2 | AA43: 3 | AJ43: 3 | AM43: 3 | AO43: 3
F44: Board | O44: 72.5 | Q44: 70 | S44: 62.5 | U44: 80 | Y44: 1 | AK44: 1
O45: 75 | U45: 82.5
O46: RPE
O52: RPE
W53: {=IF(Input!B174="SQ A", INDIRECT("squat1A"), IF(Input!B174="SQ B", INDIRECT("squat1B"), IF(Input!B174="SQ C", INDIRECT("squat1C"), IF(Input!B174="BP A", INDIRECT("benchpress1A"), IF(Input!B174="BP B", INDIRECT("benchpress1B"), IF(Input!B174="BP C", INDIRECT("benchpress1C"), IF(Input!B174="DL A", INDIRECT("deadlift1A"), IF(Input!B174="DL B", INDIRECT("deadlift1B"), IF(Input!B174="DL C", INDIRECT("deadlift1C"), "")))))))))} | AH53: {=IF(Input!B174="SQ A", INDIRECT("squat2A"), IF(Input!B174="SQ B", INDIRECT("squat2B"), IF(Input!B174="SQ C", INDIRECT("squat2C"), IF(Input!B174="BP A", INDIRECT("benchpress2A"), IF(Input!B174="BP B", INDIRECT("benchpress2B"), IF(Input!B174="BP C", INDIRECT("benchpress2C"), IF(Input!B174="DL A", INDIRECT("deadlift2A"), IF(Input!B174="DL B", INDIRECT("deadlift2B"), IF(Input!B174="DL C", INDIRECT("deadlift2C"), "")))))))))} | AS53: {=IF(Input!B174="SQ A", INDIRECT("squat3A"), IF(Input!B174="SQ B", INDIRECT("squat3B"), IF(Input!B174="SQ C", INDIRECT("squat3C"), IF(Input!B174="BP A", INDIRECT("benchpress3A"), IF(Input!B174="BP B", INDIRECT("benchpress3B"), IF(Input!B174="BP C", INDIRECT("benchpress3C"), IF(Input!B174="DL A", INDIRECT("deadlift3A"), IF(Input!B174="DL B", INDIRECT("deadlift3B"), IF(Input!B174="DL C", INDIRECT("deadlift3C"), "")))))))))} | BD53: {=IF(Input!B174="SQ A", INDIRECT("squat4A"), IF(Input!B174="SQ B", INDIRECT("squat4B"), IF(Input!B174="SQ C", INDIRECT("squat4C"), IF(Input!B174="BP A", INDIRECT("benchpress4A"), IF(Input!B174="BP B", INDIRECT("benchpress4B"), IF(Input!B174="BP C", INDIRECT("benchpress4C"), IF(Input!B174="DL A", INDIRECT("deadlift4A"), IF(Input!B174="DL B", INDIRECT("deadlift4B"), IF(Input!B174="DL C", INDIRECT("deadlift4C"), "")))))))))}
O58: RPE
C59: Assistance / Accessories
C60: Ring Rows (single arm?) | O60: 3x max
...

Sheet Definitions
A2: Volume Distribution Variant | K2: Advanced | P2: Elite
A3: 1 | B3: 35 | C3: 28 | D3: 22 | E3: 15 | G3: 50 | H3: 30 | I3: 20 | J3: 1 | K3: 33 | L3: 28 | M3: 22 | N3: 17 | O3: 1 | P3: 32 | Q3: 27 | R3: 22 | S3: 19
A4: 2a | B4: 15 | C4: 35 | D4: 28 | E4: 22 | G4: 20 | H4: 50 | I4: 30 | J4: 2a | K4: 17 | L4: 33 | M4: 28 | N4: 22 | O4: 2a | P4: 19 | Q4: 32 | R4: 27 | S4: 22
A5: 2b | B5: 28 | C5: 35 | D5: 22 | E5: 15 | G5: 30 | H5: 50 | I5: 20 | J5: 2b | K5: 28 | L5: 33 | M5: 22 | N5: 17 | O5: 2b | P5: 27 | Q5: 32 | R5: 22 | S5: 19
A6: 2c | B6: 22 | C6: 35 | D6: 28 | E6: 15 | J6: 2c | K6: 22 | L6: 33 | M6: 28 | N6: 17 | O6: 2c | P6: 22 | Q6: 32 | R6: 27 | S6: 19
A7: 3a | B7: 15 | C7: 22 | D7: 35 | E7: 28 | G7: 20 | H7: 30 | I7: 50 | J7: 3a | K7: 17 | L7: 22 | M7: 33 | N7: 28 | O7: 3a | P7: 19 | Q7: 22 | R7: 32 | S7: 27
A8: 3b | B8: 22 | C8: 28 | D8: 35 | E8: 15 | G8: 30 | H8: 20 | I8: 50 | J8: 3b | K8: 22 | L8: 28 | M8: 33 | N8: 17 | O8: 3b | P8: 22 | Q8: 27 | R8: 32 | S8: 19
A9: 3c | B9: 15 | C9: 28 | D9: 35 | E9: 22 | J9: 3c | K9: 17 | L9: 28 | M9: 33 | N9: 22 | O9: 3c | P9: 19 | Q9: 27 | R9: 32 | S9: 22
A10: 1-3a | B10: 35 | C10: 15 | D10: 28 | E10: 22 | G10: 50 | H10: 20 | I10: 30 | J10: 1-3a | K10: 33 | L10: 17 | M10: 28 | N10: 22 | O10: 1-3a | P10: 32 | Q10: 19 | R10: 27 | S10: 22
A11: 1-3b | B11: 35 | C11: 22 | D11: 28 | E11: 15 | G11: 50 | H11: 20 | I11: 30 | J11: 1-3b | K11: 33 | L11: 22 | M11: 28 | N11: 17 | O11: 1-3b | P11: 32 | Q11: 22 | R11: 27 | S11: 19
A12: 3-1a | B12: 28 | C12: 15 | D12: 35 | E12: 22 | G12: 30 | H12: 20 | I12: 50 | J12: 3-1a | K12: 28 | L12: 17 | M12: 33 | N12: 22 | O12: 3-1a | P12: 27 | Q12: 19 | R12: 32 | S12: 22
A13: 3-1b | B13: 28 | C13: 22 | D13: 35 | E13: 15 | G13: 30 | H13: 20 | I13: 50 | J13: 3-1b | K13: 28 | L13: 22 | M13: 33 | N13: 17 | O13: 3-1b | P13: 27 | Q13: 22 | R13: 32 | S13: 19
A14: 4 | B14: 15 | C14: 22 | D14: 28 | E14: 35 | J14: 4 | K14: 17 | L14: 22 | M14: 28 | N14: 33 | O14: 4 | P14: 19 | Q14: 22 | R14: 27 | S14: 32
A15: 2-4a | B15: 15 | C15: 35 | D15: 22 | E15: 28 | J15: 2-4a | K15: 17 | L15: 33 | M15: 22 | N15: 28 | O15: 2-4a | P15: 19 | Q15: 32 | R15: 22 | S15: 27
A16: 2-4b | B16: 22 | C16: 35 | D16: 15 | E16: 28 | J16: 2-4b | K16: 22 | L16: 33 | M16: 17 | N16: 28 | O16: 2-4b | P16: 22 | Q16: 32 | R16: 19 | S16: 27
A17: 4-2a | B17: 22 | C17: 28 | D17: 15 | E17: 35 | J17: 4-2a | K17: 22 | L17: 28 | M17: 17 | N17: 33 | O17: 4-2a | P17: 22 | Q17: 27 | R17: 19 | S17: 32
A18: 4-2b | B18: 15 | C18: 28 | D18: 22 | E18: 35 | J18: 4-2b | K18: 17 | L18: 28 | M18: 22 | N18: 33 | O18: 4-2b | P18: 19 | Q18: 27 | R18: 22 | S18: 32
A20: Two Session Distribution | G20: Two Week Distribution
A21: d40_60 | C21: 40 | D21: 60 | G21: MH | J21: base
A22: d35_65 | C22: 35 | D22: 65 | G22: HM | J22: advanced
A23: d30_70 | C23: 30 | D23: 70 | J23: elite
A24: d25_75 | C24: 25 | D24: 75
A25: d20_80 | C25: 20 | D25: 80
A27: Three Session Distribution | G27: Three Week Distribution
A28: d25_33_42 | B28: 25 | C28: 33 | D28: 42 | G28: LMH
A29: d20_35_45 | B29: 20 | C29: 35 | D29: 45 | G29: LHM
A30: d22_28_50 | B30: 22 | C30: 28 | D30: 50 | G30: MLH
A31: d20_30_50 | B31: 20 | C31: 30 | D31: 50 | G31: MHL
A32: d15_35_50 | B32: 15 | C32: 35 | D32: 50 | G32: HLM
A33: d15_30_55 | B33: 15 | C33: 30 | D33: 50 | G33: HML
A35: Four Session Distribution
A36: d15_22_28_35 | B36: 15 | C36: 22 | D36: 28 | E36: 35
A37: d10_20_30_40 | B37: 10 | C37: 20 | D37: 30 | E37: 40
A39: Five Session Distribution
A40: d10_15_20_25_30 | B40: 10 | C40: 15 | D40: 20 | E40: 25 | F40: 30
A43: Lift In Session
A44: --
A45: SQ A
A46: SQ B
A47: SQ C
...
